<?xml version="1.0"?>
<sdf version="1.4">
	<model name="simple_gripper">
		<link name="vertical_bar">
			<pose>0 0 0.0975 0 0 0</pose>
            <inertial>
                <pose>0 0 -0.0975 0 0 0</pose>
				<inertia>
					<ixx>0.01</ixx>
					<ixy>0</ixy>
					<ixz>0</ixz>
					<iyy>0.01</iyy>
					<iyz>0</iyz>
					<izz>0.01</izz>
				</inertia>
				<mass>10.0</mass>
			</inertial>
			<collision name="collision">
				<geometry>
					<box>
						<size>0.03 0.04 0.195</size>
					</box>
				</geometry>
			</collision>
			<visual name="visual">
				<geometry>
					<box>
						<size>0.03 0.04 0.195</size>
					</box>
				</geometry>
                <material>
                    <script>Gazebo/Black</script>
				</material>
			</visual>
		</link>
		<link name="horizontal_bar">
			<pose>0.02 0 0 0 0 0</pose>
			<inertial>
				<inertia>
					<ixx>0.01</ixx>
					<ixy>0</ixy>
					<ixz>0</ixz>
					<iyy>0.01</iyy>
					<iyz>0</iyz>
					<izz>0.01</izz>
				</inertia>
				<mass>2.0</mass>
			</inertial>
			<collision name="collision">
				<geometry>
					<box>
						<size>0.02 0.315 0.04</size>
					</box>
				</geometry>
			</collision>
			<visual name="visual">
				<geometry>
					<box>
						<size>0.02 0.315 0.04</size>
					</box>
				</geometry>
                <material>
                    <script>Gazebo/Black</script>
				</material>
			</visual>
		</link>
		<link name="left_grip">
			<pose>0.06 0.14 0 0 0 0</pose>
			<inertial>
				<inertia>
					<ixx>0.01</ixx>
					<ixy>0</ixy>
					<ixz>0</ixz>
					<iyy>0.01</iyy>
					<iyz>0</iyz>
					<izz>0.01</izz>
				</inertia>
				<mass>0.2</mass>
			</inertial>
			<collision name="collision">
				<geometry>
					<box>
						<size>0.09 0.01 0.04</size>
					</box>
				</geometry>
			</collision>
			<visual name="visual">
				<geometry>
					<box>
						<size>0.09 0.01 0.04</size>
					</box>
				</geometry>
                <material>
                    <script>Gazebo/Black</script>
				</material>
			</visual>
		</link>
		<link name="right_grip">
			<pose>0.06 -0.14 0 0 0 0</pose>
			<inertial>
				<inertia>
					<ixx>0.01</ixx>
					<ixy>0</ixy>
					<ixz>0</ixz>
					<iyy>0.01</iyy>
					<iyz>0</iyz>
					<izz>0.01</izz>
				</inertia>
				<mass>0.2</mass>
			</inertial>
			<collision name="collision">
				<geometry>
					<box>
						<size>0.09 0.01 0.04</size>
					</box>
				</geometry>
			</collision>
			<visual name="visual">
				<geometry>
					<box>
						<size>0.09 0.01 0.04</size>
					</box>
				</geometry>
                <material>
                    <script>Gazebo/Black</script>
				</material>
			</visual>
		</link>
        <static>false</static>
        <joint name="lift" type="prismatic">
            <child>horizontal_bar</child>
            <parent>vertical_bar</parent>
            <axis>
                <limit>
                    <lower>0.02</lower>
                    <upper>0.175</upper>
                </limit>
                <xyz>0 0 1</xyz>
            </axis>
        </joint>
        <joint name="grip_left" type="prismatic">
            <child>left_grip</child>
            <parent>horizontal_bar</parent>
            <axis>
                <limit>
                    <lower>-0.13</lower>
                    <upper>0</upper>
                </limit>
                <xyz>0 1 0</xyz>
            </axis>
        </joint>
        <joint name="grip_right" type="prismatic">
            <child>right_grip</child>
            <parent>horizontal_bar</parent>
            <axis>
                <limit>
                    <lower>0</lower>
                    <upper>0.13</upper>
                </limit>
                <xyz>0 1 0</xyz>
            </axis>
        </joint>
	</model>
</sdf>
