<?xml version="1.0"?>
<sdf version='1.4'>

    <model name='pioneer2dx_ros_control'>
        <link name='chassis'>
            <pose>0 0 0.16 0 -0 0</pose>
            <inertial>
                <mass>5.67</mass>
                <inertia>
                    <ixx>0.07</ixx>
                    <iyy>0.08</iyy>
                    <izz>0.1</izz>
                    <ixy>0</ixy>
                    <ixz>0</ixz>
                    <iyz>0</iyz>
                </inertia>
            </inertial>
            <collision name='collision'>
                <geometry>
                    <box>
                        <size>0.445 0.277 0.17</size>
                    </box>
                </geometry>
                <max_contacts>10</max_contacts>
                <surface>
                    <bounce/>
                    <friction>
                        <ode/>
                    </friction>
                    <contact>
                        <ode/>
                    </contact>
                </surface>
            </collision>
            <collision name='castor_collision'>
                <pose>-0.2 0 -0.12 0 -0 0</pose>
                <geometry>
                    <sphere>
                        <radius>0.04</radius>
                    </sphere>
                </geometry>
                <surface>
                    <friction>
                        <ode>
                            <mu>0</mu>
                            <mu2>0</mu2>
                            <slip1>1</slip1>
                            <slip2>1</slip2>
                        </ode>
                    </friction>
                    <bounce/>
                    <contact>
                        <ode/>
                    </contact>
                </surface>
                <max_contacts>10</max_contacts>
            </collision>
            <visual name='visual'>
                <pose>0 0 0.04 0 -0 0</pose>
                <geometry>
                    <mesh>
                        <uri>model://pioneer2dx/meshes/chassis.dae</uri>
                    </mesh>
                </geometry>
            </visual>
            <visual name='castor_visual'>
                <pose>-0.2 0 -0.12 0 -0 0</pose>
                <geometry>
                    <sphere>
                        <radius>0.04</radius>
                    </sphere>
                </geometry>
                <material>
                    <script>
                        <uri>file://media/materials/scripts/gazebo.material</uri>
                        <name>Gazebo/FlatBlack</name>
                    </script>
                </material>
            </visual>
            <velocity_decay>
                <linear>0</linear>
                <angular>0</angular>
            </velocity_decay>
            <self_collide>0</self_collide>
            <kinematic>0</kinematic>
            <gravity>1</gravity>
        </link>
        <link name='right_wheel'>
            <pose>0.1 -0.17 0.11 0 1.5707 1.5707</pose>
            <inertial>
                <mass>1.5</mass>
                <inertia>
                    <ixx>0.0051</ixx>
                    <iyy>0.0051</iyy>
                    <izz>0.009</izz>
                    <ixy>0</ixy>
                    <ixz>0</ixz>
                    <iyz>0</iyz>
                </inertia>
            </inertial>
            <collision name='collision'>
                <geometry>
                    <cylinder>
                        <radius>0.11</radius>
                        <length>0.05</length>
                    </cylinder>
                </geometry>
                <surface>
                    <friction>
                        <ode>
                            <mu>100000</mu>
                            <mu2>100000</mu2>
                            <slip1>0</slip1>
                            <slip2>0</slip2>
                        </ode>
                    </friction>
                    <bounce/>
                    <contact>
                        <ode/>
                    </contact>
                </surface>
                <max_contacts>10</max_contacts>
            </collision>
            <visual name='visual'>
                <geometry>
                    <cylinder>
                        <radius>0.11</radius>
                        <length>0.05</length>
                    </cylinder>
                </geometry>
                <material>
                    <script>
                        <uri>file://media/materials/scripts/gazebo.material</uri>
                        <name>Gazebo/FlatBlack</name>
                    </script>
                </material>
            </visual>
            <velocity_decay>
                <linear>0</linear>
                <angular>0</angular>
            </velocity_decay>
            <self_collide>0</self_collide>
            <kinematic>0</kinematic>
            <gravity>1</gravity>
        </link>
        <link name='left_wheel'>
            <pose>0.1 0.17 0.11 0 1.5707 1.5707</pose>
            <inertial>
                <mass>1.5</mass>
                <inertia>
                    <ixx>0.0051</ixx>
                    <iyy>0.0051</iyy>
                    <izz>0.009</izz>
                    <ixy>0</ixy>
                    <ixz>0</ixz>
                    <iyz>0</iyz>
                </inertia>
            </inertial>
            <collision name='collision'>
                <geometry>
                    <cylinder>
                        <radius>0.11</radius>
                        <length>0.05</length>
                    </cylinder>
                </geometry>
                <surface>
                    <friction>
                        <ode>
                            <mu>100000</mu>
                            <mu2>100000</mu2>
                            <slip1>0</slip1>
                            <slip2>0</slip2>
                        </ode>
                    </friction>
                    <bounce/>
                    <contact>
                        <ode/>
                    </contact>
                </surface>
                <max_contacts>10</max_contacts>
            </collision>
            <visual name='visual'>
                <geometry>
                    <cylinder>
                        <radius>0.11</radius>
                        <length>0.05</length>
                    </cylinder>
                </geometry>
                <material>
                    <script>
                        <uri>file://media/materials/scripts/gazebo.material</uri>
                        <name>Gazebo/FlatBlack</name>
                    </script>
                </material>
            </visual>
            <velocity_decay>
                <linear>0</linear>
                <angular>0</angular>
            </velocity_decay>
            <self_collide>0</self_collide>
            <kinematic>0</kinematic>
            <gravity>1</gravity>
        </link>
        <joint name='left_wheel_hinge' type='revolute'>
            <pose>0 0 -0.03 0 -0 0</pose>
            <child>left_wheel</child>
            <parent>chassis</parent>
            <axis>
                <xyz>0 1 0</xyz>
                <limit>
                    <lower>-1e+16</lower>
                    <upper>1e+16</upper>
                </limit>
            </axis>
        </joint>
        <joint name='right_wheel_hinge' type='revolute'>
            <pose>0 0 0.03 0 -0 0</pose>
            <child>right_wheel</child>
            <parent>chassis</parent>
            <axis>
                <xyz>0 1 0</xyz>
                <limit>
                    <lower>-1e+16</lower>
                    <upper>1e+16</upper>
                </limit>
            </axis>
        </joint>
        <static>0</static>

        <!-- GRIPPER -->
            <link name="vertical_bar">
                <pose>0.22 0 0.1075 0 0 0</pose>
                <inertial>
                    <pose>0 0 -0.0975 0 0 0</pose>
                    <inertia>
                        <ixx>0.01</ixx>
                        <ixy>0</ixy>
                        <ixz>0</ixz>
                        <iyy>0.01</iyy>
                        <iyz>0</iyz>
                        <izz>0.01</izz>
                    </inertia>
                    <mass>0.5</mass>
                </inertial>
                <collision name="collision">
                    <geometry>
                        <box>
                            <size>0.03 0.04 0.195</size>
                        </box>
                    </geometry>
                </collision>
                <visual name="visual">
                    <geometry>
                        <box>
                            <size>0.03 0.04 0.195</size>
                        </box>
                    </geometry>
                    <material>
                        <script>
                            <uri>file://media/materials/scripts/gazebo.material</uri>
                            <name>Gazebo/FlatBlack</name>
                        </script>
                    </material>
                </visual>
            </link>
            <link name="horizontal_bar">
                <pose>0.24 0 0.01 0 0 0</pose>
                <inertial>
                    <inertia>
                        <ixx>0.01</ixx>
                        <ixy>0</ixy>
                        <ixz>0</ixz>
                        <iyy>0.01</iyy>
                        <iyz>0</iyz>
                        <izz>0.01</izz>
                    </inertia>
                    <mass>0.5</mass>
                </inertial>
                <collision name="collision">
                    <geometry>
                        <box>
                            <size>0.02 0.315 0.04</size>
                        </box>
                    </geometry>
                </collision>
                <visual name="visual">
                    <geometry>
                        <box>
                            <size>0.02 0.315 0.04</size>
                        </box>
                    </geometry>
                    <material>
                        <script>
                            <uri>file://media/materials/scripts/gazebo.material</uri>
                            <name>Gazebo/FlatBlack</name>
                        </script>
                    </material>
                </visual>
            </link>
            <link name="left_grip">
                <pose>0.28 0.14 0.01 0 0 0</pose>
                <inertial>
                    <inertia>
                        <ixx>0.01</ixx>
                        <ixy>0</ixy>
                        <ixz>0</ixz>
                        <iyy>0.01</iyy>
                        <iyz>0</iyz>
                        <izz>0.01</izz>
                    </inertia>
                    <mass>0.1</mass>
                </inertial>
                <collision name="collision">
                    <geometry>
                        <box>
                            <size>0.09 0.01 0.04</size>
                        </box>
                    </geometry>
                </collision>
                <visual name="visual">
                    <geometry>
                        <box>
                            <size>0.09 0.01 0.04</size>
                        </box>
                    </geometry>
                    <material>
                        <script>
                            <uri>file://media/materials/scripts/gazebo.material</uri>
                            <name>Gazebo/FlatBlack</name>
                        </script>
                    </material>
                </visual>
            </link>
            <link name="right_grip">
                <pose>0.28 -0.14 0.01 0 0 0</pose>
                <inertial>
                    <inertia>
                        <ixx>0.01</ixx>
                        <ixy>0</ixy>
                        <ixz>0</ixz>
                        <iyy>0.01</iyy>
                        <iyz>0</iyz>
                        <izz>0.01</izz>
                    </inertia>
                    <mass>0.1</mass>
                </inertial>
                <collision name="collision">
                    <geometry>
                        <box>
                            <size>0.09 0.01 0.04</size>
                        </box>
                    </geometry>
                </collision>
                <visual name="visual">
                    <geometry>
                        <box>
                            <size>0.09 0.01 0.04</size>
                        </box>
                    </geometry>
                    <material>
                        <script>
                            <uri>file://media/materials/scripts/gazebo.material</uri>
                            <name>Gazebo/FlatBlack</name>
                        </script>
                    </material>
                </visual>
            </link>
            <joint name="lift" type="prismatic">
                <child>horizontal_bar</child>
                <parent>vertical_bar</parent>
                <axis>
                    <limit>
                        <lower>0.02</lower>
                        <upper>0.175</upper>
                    </limit>
                    <xyz>0 0 1</xyz>
                </axis>
            </joint>
            <joint name="grip_left" type="prismatic">
                <child>left_grip</child>
                <parent>horizontal_bar</parent>
                <axis>
                    <limit>
                        <lower>-0.13</lower>
                        <upper>0</upper>
                    </limit>
                    <xyz>0 1 0</xyz>
                    <dynamics>
                        <damping>10</damping>
                        <friction>10</friction>
                        <spring_reference>0</spring_reference>
                        <spring_stiffness>0</spring_stiffness>
                    </dynamics>
                </axis>
            </joint>
            <joint name="grip_right" type="prismatic">
                <child>right_grip</child>
                <parent>horizontal_bar</parent>
                <axis>
                    <limit>
                        <lower>0</lower>
                        <upper>0.13</upper>
                    </limit>
                    <xyz>0 1 0</xyz>
                    <dynamics>
                        <damping>10</damping>
                        <friction>10</friction>
                        <spring_reference>0</spring_reference>
                        <spring_stiffness>0</spring_stiffness>
                    </dynamics>
                </axis>
            </joint>

        <joint name="gripper_anchor" type="fixed">
            <child>vertical_bar</child>
            <parent>chassis</parent>
        </joint>
        
        <plugin name='differential_drive_controller' filename='libgazebo_ros_diff_drive.so'>
            <alwaysOn>true</alwaysOn>
            <updateRate>100</updateRate>
            <legacyMode>false</legacyMode>
            <leftJoint>left_wheel_hinge</leftJoint>
            <rightJoint>right_wheel_hinge</rightJoint>
            <wheelSeparation>0.39</wheelSeparation>
            <wheelDiameter>0.15</wheelDiameter>
            <torque>5</torque>
            <commandTopic>cmd_vel</commandTopic>
            <odometryTopic>odom</odometryTopic>
            <odometryFrame>odom</odometryFrame>
            <robotBaseFrame>chassis</robotBaseFrame>
            <rosDebugLevel>na</rosDebugLevel>
            <publishWheelTF>false</publishWHeelTF>
            <wheelAcceleration>0</wheelAcceleration>
            <wheelTorque>5</wheelTorque>
            <odometrySource>1</odometrySource>
            <publishTf>1</publishTf>
            <publishWheelJointState>false</publishWheelJointState>
        </plugin>
    </model>

</sdf>
